<?xml version="1.0"?>
<robot  
	xmlns:xacro="http://www.ros.org/wiki/xacro"
	name="autonomos">
  
<xacro:include filename="$(find autonomos_description)/urdf/autonomos.gazebo"/>

  <!-- Include materials -->
  <material name="Black">
    <color rgba="0.0 0.0 0.0 1.0"/>
  </material>
  <material name="Blue">
    <color rgba="0.0 0.0 0.8 1.0"/>
  </material>
  <material name="Green">
    <color rgba="0.0 0.8 0.0 1.0"/>
  </material>
  <material name="Red">
    <color rgba="0.8 0.0 0.0 1.0"/>
  </material>
  <material name="White">
    <color rgba="1.0 1.0 1.0 1.0"/>
  </material>
  
  <!-- properties -->
  <xacro:property name="ancho" value="0.01" />
  <xacro:property name="radio" value="0.020" />
  <xacro:property name="mu" value="1" />
  

  <xacro:macro name="inertial_matrix" params="mass">
      <inertial>
        <mass value="${mass}"/>
        <inertia ixx="0.0010000" ixy="0.000000" ixz="0.000000" iyy="0.0010000" iyz="0.000000" izz="0.0010000" />
      </inertial>
   </xacro:macro>
  
  
  <xacro:macro name="collision_rueda" params="length radius">
    <collision>
        <geometry>
	     <cylinder length="${length}" radius="${radius}"/>
	</geometry>
    </collision>
  </xacro:macro>

  <xacro:macro name="visual_rueda" params="length radius">
    <visual>
        <geometry>
	     <cylinder length="${ancho}" radius="${radio}"/>
	</geometry>
        <material name="Green"/>
    </visual>
  </xacro:macro>

  <xacro:macro name="friccion_rueda" params="mu">
      <surface>
        <bounce restitution_coefficient=".2" />
        <friction>
          <ode mu="${mu}" mu2="${mu}" fdir1="1 0 0" slip1="0" slip2="0" />
        </friction>
        <contact>
          <ode/>
        </contact>
      </surface>
  </xacro:macro>

  <xacro:macro name="transmission_block" params="joint_name">
   <transmission name="${joint_name}_tran">
     <type>transmission_interface/SimpleTransmission</type>
     <joint name="${joint_name}">
       <hardwareInterface>hardware_interface/EffortJointInterface</hardwareInterface>
     </joint>
     <actuator name="${joint_name}_motor">
      <hardwareInterface>hardware_interface/EffortJointInterface</hardwareInterface>
      <mechanicalReduction>1</mechanicalReduction>
     </actuator>
    </transmission>
  </xacro:macro>

<!-- VelocityJointInterface -->

  <link name="base_link">
      <!-- body -->
      <inertial>
        <origin xyz="0.002623 0.000000 0.022951"/>
        <mass value="0.61"/>
        <inertia ixx="0.611350" ixy="0.000000" ixz="0.000160" iyy="0.611606" iyz="0.000000" izz="0.610256"/>
      </inertial>
      <collision name="base_link_geom">
        <geometry>
          <box size="0.400000 0.150000 0.0500000"/>
        </geometry>
      </collision>
      <visual name="base_link_visual">
        <geometry>
          <box size="0.400000 0.150000 0.0500000"/>
        </geometry>
        <material name="Blue"/>
      </visual>
      
      <!-- pilar_front_right -->
      <collision>
	<origin rpy="0.000000 -0.385398 0.200000" xyz="0.060000 -0.074 0.045"/>
        <geometry>
          <box size="0.022 0.001 0.06"/>
        </geometry>
      </collision>
      <visual>
	<origin rpy="0.000000 -0.385398 0.2000000" xyz="0.060000 -0.075 0.045"/>
        <geometry>
          <box size="0.022 0.001 0.06"/>
        </geometry>
        <material name="Blue"/>
      </visual>
      <!-- pilar_front_left -->
      <collision>
	<origin rpy="0.000000 -0.385398 0.200000" xyz="0.060000 0.074 0.045"/>
        <geometry>
          <box size="0.022 0.001 0.06"/>
        </geometry>
      </collision>
      <visual>
	<origin rpy="0.000000 -0.385398 -0.2000000" xyz="0.060000 0.074 0.045"/>
        <geometry>
          <box size="0.022 0.001 0.06"/>
        </geometry>
        <material name="Blue"/>
      </visual>
      <!-- pilar_back_left -->
      <collision>
	<origin rpy="0.000000 0.585398 0.2000000" xyz="-0.115 0.074 0.045"/>
        <geometry>
          <box size="0.042 0.001 0.06"/>
        </geometry>
      </collision>
      <visual>
	<origin rpy="0.000000 0.585398 0.2000000" xyz="-0.115 0.074 0.045"/>
        <geometry>
          <box size="0.042 0.001 0.06"/>
        </geometry>
        <material name="Blue"/>
      </visual>
      <!-- pilar_back_right -->
      <collision>
	<origin rpy="0.000000 0.585398 -0.2000000" xyz="-0.115 -0.074 0.045"/>
        <geometry>
          <box size="0.042 0.001 0.06"/>
        </geometry>
      </collision>
      <visual>
	<origin rpy="0.000000 0.585398 -0.2000000" xyz="-0.115 -0.074 0.045"/>
        <geometry>
          <box size="0.042 0.001 0.06"/>
        </geometry>
        <material name="Blue"/>
      </visual>
      <!-- ceiling -->
      <collision>
	<origin rpy="1.57 0 0" xyz="-0.035 0.0 0.07"/>
        <geometry>
          <box size="0.17 0.01 0.15"/>
        </geometry>
      </collision>
      <visual>
	<origin rpy="1.57 0 0" xyz="-0.035 0.0 0.07"/>
        <geometry>
          <box size="0.17 0.01 0.15"/>
        </geometry>
        <material name="Blue"/>
      </visual>
  </link>

  <!-- back left wheel -->
  <link name="back_left_wheel_link">
    <xacro:visual_rueda length="${ancho}" radius="${radio}"/>
    <xacro:collision_rueda length="${ancho}" radius="${radio}"/>
    <xacro:inertial_matrix mass="0.01"/>
    <xacro:friccion_rueda mu="${mu}" />
  </link>

  <joint name="back_left_wheel_joint" type="revolute">
    <parent link="base_link"/>
    <child link="back_left_wheel_link"/>
    <origin rpy="1.57 0 0" xyz="-0.160000 0.100000 -0.030000"/>
    <axis xyz="0 0 1"/>
    <limit effort="300" lower="-10000000000000000" upper="10000000000000000" velocity="1"/>
    <!-- Al utilizar esto en gazebo, los joints no funcionan -->
    <!-- <dynamics damping="50" friction="1"/> -->
  </joint>

  <!-- back right wheel -->
  <link name="back_right_wheel_link">
     <xacro:visual_rueda length="${ancho}" radius="${radio}"/>
     <xacro:collision_rueda length="${ancho}" radius="${radio}"/>
     <xacro:inertial_matrix mass="0.01"/>
     <xacro:friccion_rueda mu="${mu}" />
  </link>

  <joint name="back_right_wheel_joint" type="revolute">
    <parent link="base_link"/>
    <child link="back_right_wheel_link"/>
    <origin rpy="1.57 0 0" xyz="-0.160000 -0.100000 -0.0300000"/>
    <axis xyz="0 0 1"/>
    <limit effort="300" lower="-10000000000000000" upper="10000000000000000" velocity="1"/>
    <!-- <dynamics damping="50" friction="1"/> -->
  </joint>

  <!-- Front link of Ackermann -->
  <!-- Joins to the car body -->
  <link name="front_link">
    <!-- link_geom_front -->
    <collision>
        <!-- <origin xyz="0.160000 0.000000 -0.0500000"/> -->
        <geometry>
          <box size="0.020000 0.150000 0.005000"/>
        </geometry>
    </collision>
    <visual>
        <geometry>
          <box size="0.020000 0.150000 0.005000"/>
        </geometry>
        <material name="Red"/>
    </visual>
    <xacro:inertial_matrix mass="0.001"/>
  </link>
  <joint name="front_joint" type="fixed">
    	<parent link="base_link"/>
    	<child link="front_link"/>
    	<origin xyz="0.160000 0.000000 -0.0300000 "/>
  </joint>

  <!-- front left bar -->  
  <link name="front_left_bar_link">
      <xacro:inertial_matrix mass="0.001"/>
      <collision>
        <geometry>
          <box size="0.04 0.02 0.005"/>
        </geometry>
      </collision>
      <visual>
        <geometry>
          <box size="0.04 0.02 0.005"/>
        </geometry>
        <material name="Red"/>
      </visual>
  </link>

  <joint name="front_left_bar_joint" type="revolute">
    <parent link="front_link"/>
    <child link="front_left_bar_link"/>
    <origin rpy="0 0 0" xyz="-0.0200 0.060000 0.000000"/>
    <axis xyz="0 0 1"/>
    <limit effort="300" lower="-0.5" upper="0.5" velocity="1"/>
    <!-- <dynamics damping="50" friction="1"/> -->
  </joint>

  <!-- front left wheel -->
  <link name="front_left_wheel_link">
    <xacro:visual_rueda length="${ancho}" radius="${radio}"/>
    <xacro:collision_rueda length="${ancho}" radius="${radio}"/>
    <xacro:inertial_matrix mass="0.01"/>
    <xacro:friccion_rueda mu="${mu}" />
  </link>

  <joint name="front_left_wheel_joint" type="revolute">
    <parent link="front_left_bar_link"/>
    <child link="front_left_wheel_link"/>
    <origin rpy="1.57 0 0" xyz="0.000000 0.040000 0.000000"/>
    <axis xyz="0 0 1"/>
    <limit effort="300" lower="-10000000000000000" upper="10000000000000000" velocity="1"/>
    <!-- <dynamics damping="50" friction="1"/> -->
  </joint>

  <!-- front right bar -->
  <link name="front_right_bar_link">
      <xacro:inertial_matrix mass="0.001"/>
      <collision>
        <geometry>
          <box size="0.04 0.02 0.005"/>
        </geometry>
      </collision>
      <visual>
        <geometry>
          <box size="0.04 0.02 0.005"/>
        </geometry>
        <material name="Red"/>
      </visual>
  </link>
  
  <joint name="front_right_bar_joint" type="revolute">
    <parent link="front_link"/>
    <child link="front_right_bar_link"/>
    <origin rpy="0 0 0" xyz="-0.020000 -0.060000 0.000000"/>
    <axis xyz="0 0 1"/>
    <limit effort="300" lower="-0.5" upper="0.5" velocity="1"/>
    <!-- <dynamics damping="50" friction="1"/> -->
  </joint>

  <!-- front right wheel -->
  <link name="front_right_wheel_link">
    <xacro:visual_rueda length="${ancho}" radius="${radio}"/>
    <xacro:collision_rueda length="${ancho}" radius="${radio}"/>
    <xacro:inertial_matrix mass="0.01"/>
    <xacro:friccion_rueda mu="${mu}" />
  </link>

  <joint name="front_right_wheel_joint" type="revolute">
    <parent link="front_right_bar_link"/>
    <child link="front_right_wheel_link"/>
    <origin rpy="1.57 0 0" xyz="0.0000 -0.04000 0.000000"/>
    <axis xyz="0 0 1"/>
    <limit effort="300" lower="-10000000000000000" upper="10000000000000000" velocity="1"/>
    <!-- <dynamics damping="50" friction="1"/> -->
  </joint>
  
  <!-- steer link -->
  <link name="steer_link">
      <xacro:inertial_matrix mass="0.001"/>
      <collision>
        <geometry>
          <box size="0.04 0.02 0.005"/>
        </geometry>
      </collision>
      <visual>
        <geometry>
          <box size="0.04 0.02 0.005"/>
        </geometry>
        <material name="Red"/>
      </visual>
  </link>
  
  <joint name="steer_joint" type="revolute">
    <parent link="front_link"/>
    <child link="steer_link"/>
    <origin rpy="0 0 0" xyz="-0.020000 0.000000 0.000000"/>
    <axis xyz="0 0 1"/>
    <limit effort="300" lower="-0.5" upper="0.5" velocity="1"/>
    <!-- <dynamics damping="50" friction="1"/> -->
  </joint>

  <!-- <xacro:transmission_block joint_name="steer_joint"/> -->

  <!-- ackerman link -->
  <link name="ackermann_bar_link">
      <xacro:inertial_matrix mass="0.001"/>
      <collision>
        <geometry>
          <box size="0.020000 0.150000 0.0050000"/>
        </geometry>
      </collision>
      <visual>
        <geometry>
          <box size="0.020000 0.150000 0.0050000"/>
        </geometry>
        <material name="Red"/>
      </visual>
  </link>
  
  <joint name="ackermann_joint" type="revolute">
    <parent link="steer_link"/>
    <child link="ackermann_bar_link"/>
    <origin rpy="0 0 0" xyz="-0.020 0.000000 0.000000"/>
    <axis xyz="0 0 1"/>
    <limit effort="300" lower="-0.5" upper="0.5" velocity="1"/>
    <!-- <dynamics damping="50" friction="1"/> -->
  </joint>
  
  <!-- laser link -->
  <link name="laser_link">
    <inertial>
      <mass value="0.1197"/>
      <inertia ixx="0.00000429247" ixy="0.00000000000" ixz="0.00000002565" iyy="0.00000008027" iyz="0.00000000000" izz="0.00000427339"/>
    </inertial>
    <collision>
<!-- <origin xyz="0.000000 0.000000 0.075000"/> -->
        <geometry>
          <box size="0.05 0.05 0.035"/>
        </geometry>
    </collision>
    <visual>
<!-- <origin xyz="0.000000 0.000000 0.07000"/> -->
        <geometry>
          <cylinder radius="0.025" length="0.04"/>
        </geometry>
        <material name="Green"/>
    </visual>
  </link>

  <joint name="laser_joint" type="fixed">
    <origin rpy="0 0 0" xyz="-0.03 0 .04"/>
    <parent link="base_link"/>
    <child link="laser_link"/>
  </joint>

  <link name="camera_link">
      <xacro:inertial_matrix mass="0.001"/>
      <collision name="collision">
        <geometry>
          <box size="0.010000 0.010000 0.010000"/>
        </geometry>
      </collision>
      <visual name="visual">
        <geometry>
          <box size="0.010000 0.010000 0.010000"/>
        </geometry>
      </visual>
  </link>

  <joint name="camera_joint" type="fixed">
    <origin rpy="0 0.1 0" xyz="0.03 0.0 0.09"/>
    <parent link="base_link"/>
    <child link="camera_link"/>
    <axis xyz="0 0 1"/>
  </joint>
  
</robot>
